Workbook

Sheet Malayan Banking Stock Price His
A1: Date | B1: Price | C1: Vol. (M) | D1: Vol. | E1: Change % | F1: Calculation
A2: 45139 | B2: 8.86 | C2: 40.61 | D2: =C2*1000000 -> 40610000 | E2: 0.0103
A3: 01/15/2023 | B3: 8.8 | C3: 53.28 | D3: =C3*1000000 -> 53280000 | E3: -0.0068 | F3: =B3/B2-1 -> -0.006772009 | H3: AVG | I3: =AVERAGE(B2:B150) -> 9.5844966
A4: 01/22/2023 | B4: 8.74 | C4: 18.44 | D4: =C4*1000000 -> 18440000 | E4: -0.0068 | H4: SD | I4: =_xlfn.STDEV.S(B2:B150) -> 0.64605606
A5: 01/29/2023 | B5: 8.71 | C5: 47.88 | D5: =C5*1000000 -> 47880000 | E5: -0.0034 | H5: Max | I5: =MAX(B2:B150) -> 10.8
A6: 45048 | B6: 8.75 | C6: 37.66 | D6: =C6*1000000 -> 37660000 | E6: 0.0046 | H6: Min | I6: =MIN(B2:B150) -> 8.38
A7: 45262 | B7: 8.75 | C7: 43.34 | D7: =C7*1000000 -> 43340000 | E7: 0
A8: 02/19/2023 | B8: 8.74 | C8: 22.05 | D8: =C8*1000000 -> 22050000 | E8: -0.0011
A9: 02/26/2023 | B9: 8.71 | C9: 49.55 | D9: =C9*1000000 -> 49550000 | E9: -0.0034
A10: 45049 | B10: 8.7 | C10: 48.68 | D10: =C10*1000000 -> 48680000 | E10: -0.0011
A11: 45263 | B11: 8.38 | C11: 57.35 | D11: =C11*1000000 -> 57350000 | E11: -0.0368
A12: 03/19/2023 | B12: 8.43 | C12: 22.18 | D12: =C12*1000000 -> 22180000 | E12: 0.006
A13: 03/26/2023 | B13: 8.57 | C13: 25.09 | D13: =C13*1000000 -> 25090000 | E13: 0.0166
A14: 44961 | B14: 8.66 | C14: 19.39 | D14: =C14*1000000 -> 19390000 | E14: 0.0105
A15: 45173 | B15: 8.71 | C15: 32.02 | D15: =C15*1000000 -> 32020000 | E15: 0.0058
A16: 04/16/2023 | B16: 8.7 | C16: 19.05 | D16: =C16*1000000 -> 19050000 | E16: -0.0011
A17: 04/23/2023 | B17: 8.66 | C17: 27.47 | D17: =C17*1000000 -> 27470000 | E17: -0.0046
A18: 04/30/2023 | B18: 8.75 | C18: 18.05 | D18: =C18*1000000 -> 18050000 | E18: 0.0104
A19: 45112 | B19: 8.69 | C19: 27.97 | D19: =C19*1000000 -> 27970000 | E19: -0.0069
A20: 05/14/2023 | B20: 8.78 | C20: 19.66 | D20: =C20*1000000 -> 19660000 | E20: 0.0104
A21: 05/21/2023 | B21: 8.58 | C21: 42.49 | D21: =C21*1000000 -> 42490000 | E21: -0.0228
A22: 05/28/2023 | B22: 8.58 | C22: 90.71 | D22: =C22*1000000 -> 90710000 | E22: 0
A23: 45022 | B23: 8.62 | C23: 21.69 | D23: =C23*1000000 -> 21690000 | E23: 0.0047
A24: 45236 | B24: 8.57 | C24: 39.75 | D24: =C24*1000000 -> 39750000 | E24: -0.0058
A25: 06/18/2023 | B25: 8.74 | C25: 28.97 | D25: =C25*1000000 -> 28970000 | E25: 0.0198
A26: 06/25/2023 | B26: 8.63 | C26: 28.3 | D26: =C26*1000000 -> 28300000 | E26: -0.0126
A27: 44964 | B27: 8.67 | C27: 25.2 | D27: =C27*1000000 -> 25200000 | E27: 0.0046
A28: 45176 | B28: 8.8 | C28: 36.57 | D28: =C28*1000000 -> 36570000 | E28: 0.015
A29: 07/16/2023 | B29: 8.78 | C29: 30.45 | D29: =C29*1000000 -> 30450000 | E29: -0.0023
A30: 07/23/2023 | B30: 8.99 | C30: 53.4 | D30: =C30*1000000 -> 53400000 | E30: 0.0239
A31: 07/30/2023 | B31: 8.91 | C31: 43.64 | D31: =C31*1000000 -> 43640000 | E31: -0.0089
A32: 45085 | B32: 9.02 | C32: 56.96 | D32: =C32*1000000 -> 56960000 | E32: 0.0123
A33: 08/13/2023 | B33: 9 | C33: 45.79 | D33: =C33*1000000 -> 45790000 | E33: -0.0022
A34: 08/20/2023 | B34: 9.02 | C34: 43.68 | D34: =C34*1000000 -> 43680000 | E34: 0.0022
A35: 08/27/2023 | B35: 9.15 | C35: 45.38 | D35: =C35*1000000 -> 45380000 | E35: 0.0144
A36: 44994 | B36: 9.14 | C36: 36.63 | D36: =C36*1000000 -> 36630000 | E36: -0.0011
A37: 45208 | B37: 8.91 | C37: 59.45 | D37: =C37*1000000 -> 59450000 | E37: -0.0252
A38: 09/17/2023 | B38: 8.88 | C38: 33.34 | D38: =C38*1000000 -> 33340000 | E38: -0.0034
A39: 09/24/2023 | B39: 8.79 | C39: 37.51 | D39: =C39*1000000 -> 37510000 | E39: -0.0101
A40: 44936 | B40: 8.77 | C40: 76.25 | D40: =C40*1000000 -> 76250000 | E40: -0.0023
...

Sheet In-Sample
A1: Date | B1: Price | C1: Vol. (M) | D1: Change % | E1: Weekly Log Return | F1: Raw Drift | G1: Volatility | H1: Annualised Volatility | I1: Market Drift | J1: Average Price
A2: 45139 | B2: 8.86 | C2: 40.61 | D2: 0.0103
A3: 01/15/2023 | B3: 8.8 | C3: 53.28 | D3: -0.0068 | E3: =LN(B3/B2) -> -0.0067950431
A4: 01/22/2023 | B4: 8.74 | C4: 18.44 | D4: -0.0068 | E4: =LN(B4/B3) -> -0.0068415318
A5: 01/29/2023 | B5: 8.71 | C5: 47.88 | D5: -0.0034 | E5: =LN(B5/B4) -> -0.0034383988
A6: 45048 | B6: 8.75 | C6: 37.66 | D6: 0.0046 | E6: =LN(B6/B5) -> 0.0045819095
A7: 45262 | B7: 8.75 | C7: 43.34 | D7: 0 | E7: =LN(B7/B6) -> 0
A8: 02/19/2023 | B8: 8.74 | C8: 22.05 | D8: -0.0011 | E8: =LN(B8/B7) -> -0.0011435107
A9: 02/26/2023 | B9: 8.71 | C9: 49.55 | D9: -0.0034 | E9: =LN(B9/B8) -> -0.0034383988
A10: 45049 | B10: 8.7 | C10: 48.68 | D10: -0.0011 | E10: =LN(B10/B9) -> -0.0011487652
A11: 45263 | B11: 8.38 | C11: 57.35 | D11: -0.0368 | E11: =LN(B11/B10) -> -0.037475111
A12: 03/19/2023 | B12: 8.43 | C12: 22.18 | D12: 0.006 | E12: =LN(B12/B11) -> 0.0059488575
A13: 03/26/2023 | B13: 8.57 | C13: 25.09 | D13: 0.0166 | E13: =LN(B13/B12) -> 0.016470961
A14: 44961 | B14: 8.66 | C14: 19.39 | D14: 0.0105 | E14: =LN(B14/B13) -> 0.01044699
A15: 45173 | B15: 8.71 | C15: 32.02 | D15: 0.0058 | E15: =LN(B15/B14) -> 0.0057570683
A16: 04/16/2023 | B16: 8.7 | C16: 19.05 | D16: -0.0011 | E16: =LN(B16/B15) -> -0.0011487652
A17: 04/23/2023 | B17: 8.66 | C17: 27.47 | D17: -0.0046 | E17: =LN(B17/B16) -> -0.0046083031
A18: 04/30/2023 | B18: 8.75 | C18: 18.05 | D18: 0.0104 | E18: =LN(B18/B17) -> 0.010338978
A19: 45112 | B19: 8.69 | C19: 27.97 | D19: -0.0069 | E19: =LN(B19/B18) -> -0.0068807611
A20: 05/14/2023 | B20: 8.78 | C20: 19.66 | D20: 0.0104 | E20: =LN(B20/B19) -> 0.010303468
A21: 05/21/2023 | B21: 8.58 | C21: 42.49 | D21: -0.0228 | E21: =LN(B21/B20) -> -0.023042494
A22: 05/28/2023 | B22: 8.58 | C22: 90.71 | D22: 0 | E22: =LN(B22/B21) -> 0
A23: 45022 | B23: 8.62 | C23: 21.69 | D23: 0.0047 | E23: =LN(B23/B22) -> 0.0046511712
A24: 45236 | B24: 8.57 | C24: 39.75 | D24: -0.0058 | E24: =LN(B24/B23) -> -0.0058173521
A25: 06/18/2023 | B25: 8.74 | C25: 28.97 | D25: 0.0198 | E25: =LN(B25/B24) -> 0.019642457
A26: 06/25/2023 | B26: 8.63 | C26: 28.3 | D26: -0.0126 | E26: =LN(B26/B25) -> -0.012665685
A27: 44964 | B27: 8.67 | C27: 25.2 | D27: 0.0046 | E27: =LN(B27/B26) -> 0.0046242857
A28: 45176 | B28: 8.8 | C28: 36.57 | D28: 0.015 | E28: =LN(B28/B27) -> 0.014882931
A29: 07/16/2023 | B29: 8.78 | C29: 30.45 | D29: -0.0023 | E29: =LN(B29/B28) -> -0.0022753138
A30: 07/23/2023 | B30: 8.99 | C30: 53.4 | D30: 0.0239 | E30: =LN(B30/B29) -> 0.023636441
A31: 07/30/2023 | B31: 8.91 | C31: 43.64 | D31: -0.0089 | E31: =LN(B31/B30) -> -0.008938607
A32: 45085 | B32: 9.02 | C32: 56.96 | D32: 0.0123 | E32: =LN(B32/B31) -> 0.012270093
A33: 08/13/2023 | B33: 9 | C33: 45.79 | D33: -0.0022 | E33: =LN(B33/B32) -> -0.0022197567
A34: 08/20/2023 | B34: 9.02 | C34: 43.68 | D34: 0.0022 | E34: =LN(B34/B33) -> 0.0022197567
A35: 08/27/2023 | B35: 9.15 | C35: 45.38 | D35: 0.0144 | E35: =LN(B35/B34) -> 0.014309545
A36: 44994 | B36: 9.14 | C36: 36.63 | D36: -0.0011 | E36: =LN(B36/B35) -> -0.0010934938
A37: 45208 | B37: 8.91 | C37: 59.45 | D37: -0.0252 | E37: =LN(B37/B36) -> -0.025486144
A38: 09/17/2023 | B38: 8.88 | C38: 33.34 | D38: -0.0034 | E38: =LN(B38/B37) -> -0.0033726845
A39: 09/24/2023 | B39: 8.79 | C39: 37.51 | D39: -0.0101 | E39: =LN(B39/B38) -> -0.010186845
A40: 44936 | B40: 8.77 | C40: 76.25 | D40: -0.0023 | E40: =LN(B40/B39) -> -0.0022779053
...

Sheet Out Sample Forecast Summary
A2: Date | B2: Actual Price | C2: Vol. (M) | D2: Change % | E2: Weekly Log Return | F2: Raw Drift | G2: Volatility | H2: Annualised Volatility | I2: Market Drift | J2: Average Price (Rolling) | K2: Lower Limit (CI) | L2: Upper Limit (CI) | M2: Confidence Interval (Avg Price) | N2: Forecasted Price | O2: Lower Limit (CI) | P2: Upper Limit (CI) | Q2: Confidence Interval (Forecasted Price) | R2: Forecasted Price (With Dividend) | S2: Percentage Error | T2: Percentage Error (Dividend) | U2: MPE | V2: MPE (Dividend)
A3: 45847 | B3: 9.87 | C3: 56.57 | D3: -0.012 | E3: ='In-Sample'!E141 -> -0.012084739 | F3: ='In-Sample'!F141 -> -0.0014446275 | G3: ='In-Sample'!G141 -> 0.013827992 | H3: ='In-Sample'!H141 -> 0.0019175974 | I3: ='In-Sample'!I141 -> -0.0014464661 | J3: ='In-Sample'!J141 -> 10.106154 | U3: ='Out Sample Forecast'!Q1 -> 0.00067637454 | V3: ='Out Sample Forecast (Dividend)'!M2 -> 0.001848666
A4: 09/14/2025 | B4: 9.8 | C4: 33.54 | D4: -0.0071 | E4: ='In-Sample'!E142 -> -0.0071174678 | F4: ='In-Sample'!F142 -> -0.0015090695 | G4: ='In-Sample'!G142 -> 0.01384682 | H4: ='In-Sample'!H142 -> 0.0019202084 | I4: ='In-Sample'!I142 -> -0.0015109131 | J4: ='In-Sample'!J142 -> 10.090769 | K4: =J4*EXP(I4-1.96*H4) -> 10.037685 | L4: =J4*EXP(I4+1.96*H4) -> 10.113526 | M4: =L4-K4 -> 0.075840914 | N4: ='Out Sample Forecast'!J3 -> 9.8698257 | O4: ='Out Sample Forecast'!K3 -> 9.8179042 | P4: ='Out Sample Forecast'!L3 -> 9.8920845 | Q4: ='Out Sample Forecast'!M3 -> 0.074180331 | R4: ='Out Sample Forecast (Dividend)'!K3 -> 9.8581625 | S4: ='Out Sample Forecast'!O3 -> -0.0071250724 | T4: ='Out Sample Forecast (Dividend)'!L3 -> -0.0059349458
A5: 09/21/2025 | B5: 9.89 | C5: 50.26 | D5: 0.0092 | E5: ='In-Sample'!E143 -> 0.00914176 | F5: ='In-Sample'!F143 -> -0.0011509829 | G5: ='In-Sample'!G143 -> 0.013877413 | H5: ='In-Sample'!H143 -> 0.0019244509 | I5: ='In-Sample'!I143 -> -0.0011528347 | J5: ='In-Sample'!J143 -> 10.079038 | K5: =J5*EXP(I5-1.96*H5) -> 10.029524 | L5: =J5*EXP(I5+1.96*H5) -> 10.105471 | M5: =L5-K5 -> 0.075947306 | N5: ='Out Sample Forecast'!J4 -> 9.7996146 | O5: ='Out Sample Forecast'!K4 -> 9.7514726 | P5: ='Out Sample Forecast'!L4 -> 9.8253144 | Q5: ='Out Sample Forecast'!M4 -> 0.073841799 | R5: ='Out Sample Forecast (Dividend)'!K4 -> 9.788254 | S5: ='Out Sample Forecast'!O4 -> 0.0091390652 | T5: ='Out Sample Forecast (Dividend)'!L4 -> 0.01028777
A6: 09/28/2025 | B6: 10 | C6: 54.95 | D6: 0.0111 | E6: ='In-Sample'!E144 -> 0.011060947 | F6: ='In-Sample'!F144 -> -0.00093827239 | G6: ='In-Sample'!G144 -> 0.013979793 | H6: ='In-Sample'!H144 -> 0.0019386485 | I6: ='In-Sample'!I144 -> -0.00094015157 | J6: ='In-Sample'!J144 -> 10.069423 | K6: =J6*EXP(I6-1.96*H6) -> 10.021808 | L6: =J6*EXP(I6+1.96*H6) -> 10.098259 | M6: =L6-K6 -> 0.076450879 | N6: ='Out Sample Forecast'!J5 -> 9.8897739 | O6: ='Out Sample Forecast'!K5 -> 9.8430082 | P6: ='Out Sample Forecast'!L5 -> 9.9180951 | Q6: ='Out Sample Forecast'!M5 -> 0.075086914 | R6: ='Out Sample Forecast (Dividend)'!K5 -> 9.8781999 | S6: ='Out Sample Forecast'!O5 -> 0.011022615 | T6: ='Out Sample Forecast (Dividend)'!L5 -> 0.012180015
A7: 45787 | B7: 9.95 | C7: 37.35 | D7: -0.005 | E7: ='In-Sample'!E145 -> -0.0050125418 | F7: ='In-Sample'!F145 -> -0.0011442448 | G7: ='In-Sample'!G145 -> 0.013958987 | H7: ='In-Sample'!H145 -> 0.0019357632 | I7: ='In-Sample'!I145 -> -0.0011461183 | J7: ='In-Sample'!J145 -> 10.057692 | K7: =J7*EXP(I7-1.96*H7) -> 10.008128 | L7: =J7*EXP(I7+1.96*H7) -> 10.08436 | M7: =L7-K7 -> 0.076232459 | N7: ='Out Sample Forecast'!J6 -> 9.9997823 | O7: ='Out Sample Forecast'!K6 -> 9.950503 | P7: ='Out Sample Forecast'!L6 -> 10.026297 | Q7: ='Out Sample Forecast'!M6 -> 0.075793529 | R7: ='Out Sample Forecast (Dividend)'!K6 -> 9.9880983 | S7: ='Out Sample Forecast'!O6 -> -0.0050032432 | T7: ='Out Sample Forecast (Dividend)'!L6 -> -0.0038289781
A8: 46001 | B8: 9.89 | C8: 53.41 | D8: -0.006 | E8: ='In-Sample'!E146 -> -0.0060484055 | F8: ='In-Sample'!F146 -> -0.0014418129 | G8: ='In-Sample'!G146 -> 0.013894034 | H8: ='In-Sample'!H146 -> 0.0019267559 | I8: ='In-Sample'!I146 -> -0.0014436691 | J8: ='In-Sample'!J146 -> 10.042885 | K8: =J8*EXP(I8-1.96*H8) -> 9.9905962 | L8: =J8*EXP(I8+1.96*H8) -> 10.06634 | M8: =L8-K8 -> 0.075743486 | N8: ='Out Sample Forecast'!J7 -> 9.9498009 | O8: ='Out Sample Forecast'!K7 -> 9.8979972 | P8: ='Out Sample Forecast'!L7 -> 9.9730386 | Q8: ='Out Sample Forecast'!M7 -> 0.075041448 | R8: ='Out Sample Forecast (Dividend)'!K7 -> 9.9381108 | S8: ='Out Sample Forecast'!O7 -> -0.0060466036 | T8: ='Out Sample Forecast (Dividend)'!L7 -> -0.0048645918
A9: 10/19/2025 | B9: 9.9 | C9: 43.01 | D9: 0.001 | E9: ='In-Sample'!E147 -> 0.0010106115 | F9: ='In-Sample'!F147 -> -0.001204669 | G9: ='In-Sample'!G147 -> 0.013827188 | H9: ='In-Sample'!H147 -> 0.001917486 | I9: ='In-Sample'!I147 -> -0.0012065073 | J9: ='In-Sample'!J147 -> 10.030577 | K9: =J9*EXP(I9-1.96*H9) -> 9.9809007 | L9: =J9*EXP(I9+1.96*H9) -> 10.056205 | M9: =L9-K9 -> 0.075304551 | N9: ='Out Sample Forecast'!J8 -> 9.8896944 | O9: ='Out Sample Forecast'!K8 -> 9.8407159 | P9: ='Out Sample Forecast'!L8 -> 9.9149628 | Q9: ='Out Sample Forecast'!M8 -> 0.074246875 | R9: ='Out Sample Forecast (Dividend)'!K8 -> 9.8781083 | S9: ='Out Sample Forecast'!O8 -> 0.0010409676 | T9: ='Out Sample Forecast (Dividend)'!L8 -> 0.0022112835
A10: 10/26/2025 | B10: 9.87 | C10: 47.13 | D10: -0.003 | E10: ='In-Sample'!E148 -> -0.0030349037 | F10: ='In-Sample'!F148 -> -0.0010058837 | G10: ='In-Sample'!G148 -> 0.013722748 | H10: ='In-Sample'!H148 -> 0.0019030028 | I10: ='In-Sample'!I148 -> -0.0010076944 | J10: ='In-Sample'!J148 -> 10.020385 | K10: =J10*EXP(I10-1.96*H10) -> 9.9730245 | L10: =J10*EXP(I10+1.96*H10) -> 10.047699 | M10: =L10-K10 -> 0.074674661 | N10: ='Out Sample Forecast'!J9 -> 9.8999354 | O10: ='Out Sample Forecast'!K9 -> 9.8531446 | P10: ='Out Sample Forecast'!L9 -> 9.9269216 | Q10: ='Out Sample Forecast'!M9 -> 0.07377704 | R10: ='Out Sample Forecast (Dividend)'!K9 -> 9.8882031 | S10: ='Out Sample Forecast'!O9 -> -0.0030329666 | T10: ='Out Sample Forecast (Dividend)'!L9 -> -0.0018442841
A11: 45699 | B11: 9.91 | C11: 56.07 | D11: 0.0041 | E11: ='In-Sample'!E149 -> 0.0040444949 | F11: ='In-Sample'!F149 -> -0.0011121329 | G11: ='In-Sample'!G149 -> 0.01366051 | H11: ='In-Sample'!H149 -> 0.0018943719 | I11: ='In-Sample'!I149 -> -0.0011139272 | J11: ='In-Sample'!J149 -> 10.009038 | K11: =J11*EXP(I11-1.96*H11) -> 9.9608423 | L11: =J11*EXP(I11+1.96*H11) -> 10.035086 | M11: =L11-K11 -> 0.074243922 | N11: ='Out Sample Forecast'!J10 -> 9.8697342 | O11: ='Out Sample Forecast'!K10 -> 9.8222088 | P11: ='Out Sample Forecast'!L10 -> 9.8954194 | Q11: ='Out Sample Forecast'!M10 -> 0.073210606 | R11: ='Out Sample Forecast (Dividend)'!K10 -> 9.858239 | S11: ='Out Sample Forecast'!O10 -> 0.0040631464 | T11: ='Out Sample Forecast (Dividend)'!L10 -> 0.0052231045
A12: 45911 | B12: 9.93 | C12: 47.19 | D12: 0.002 | E12: ='In-Sample'!E150 -> 0.0020161297 | F12: ='In-Sample'!F150 -> -0.00081522613 | G12: ='In-Sample'!G150 -> 0.013555066 | H12: ='In-Sample'!H150 -> 0.0018797495 | I12: ='In-Sample'!I150 -> -0.00081699286 | J12: ='In-Sample'!J150 -> 10.000769 | K12: =J12*EXP(I12-1.96*H12) -> 9.9558539 | L12: =J12*EXP(I12+1.96*H12) -> 10.029486 | M12: =L12-K12 -> 0.073631833 | N12: ='Out Sample Forecast'!J11 -> 9.9098474 | O12: ='Out Sample Forecast'!K11 -> 9.8653405 | P12: ='Out Sample Forecast'!L11 -> 9.9383029 | Q12: ='Out Sample Forecast'!M11 -> 0.07296241 | R12: ='Out Sample Forecast (Dividend)'!K11 -> 9.8981384 | S12: ='Out Sample Forecast'!O11 -> 0.0020294629 | T12: ='Out Sample Forecast (Dividend)'!L11 -> 0.003208621

Sheet Out Sample Forecast
A1: Date | B1: Price | C1: Vol. (M) | D1: Change % | E1: Weekly Log Return | F1: Raw Drift | G1: Volatility | H1: Annualised Volatility | I1: Market Drift | J1: Forecasted Price (Mean) | K1: Lower Limit (CI) | L1: Upper Limit (CI) | M1: Range | O1: Percentage Error | P1: MPE | Q1: =AVERAGE(O3:O11) -> 0.00067637454
A2: 45847 | B2: 9.87 | C2: 56.57 | D2: -0.012 | E2: ='In-Sample'!E141 -> -0.012084739 | F2: ='In-Sample'!F141 -> -0.0014446275 | G2: ='In-Sample'!G141 -> 0.013827992 | H2: ='In-Sample'!H141 -> 0.0019175974 | I2: ='In-Sample'!I141 -> -0.0014464661
A3: 09/14/2025 | B3: 9.8 | C3: 33.54 | D3: -0.0071 | E3: ='In-Sample'!E142 -> -0.0071174678 | F3: ='In-Sample'!F142 -> -0.0015090695 | G3: ='In-Sample'!G142 -> 0.01384682 | H3: ='In-Sample'!H142 -> 0.0019202084 | I3: ='In-Sample'!I142 -> -0.0015109131 | J3: =AVERAGE(B15:SG15) -> 9.8698257 | K3: =J3*EXP(I3-1.96*H3) -> 9.8179042 | L3: =$J3*EXP(I3+1.96*H3) -> 9.8920845 | M3: =L3-K3 -> 0.074180331 | O3: =(B3-J3)/B3 -> -0.0071250724
A4: 09/21/2025 | B4: 9.89 | C4: 50.26 | D4: 0.0092 | E4: ='In-Sample'!E143 -> 0.00914176 | F4: ='In-Sample'!F143 -> -0.0011509829 | G4: ='In-Sample'!G143 -> 0.013877413 | H4: ='In-Sample'!H143 -> 0.0019244509 | I4: ='In-Sample'!I143 -> -0.0011528347 | J4: =AVERAGE(B16:SG16) -> 9.7996146 | K4: =J4*EXP(I4-1.96*H4) -> 9.7514726 | L4: =$J4*EXP(I4+1.96*H4) -> 9.8253144 | M4: =L4-K4 -> 0.073841799 | O4: =(B4-J4)/B4 -> 0.0091390652
A5: 09/28/2025 | B5: 10 | C5: 54.95 | D5: 0.0111 | E5: ='In-Sample'!E144 -> 0.011060947 | F5: ='In-Sample'!F144 -> -0.00093827239 | G5: ='In-Sample'!G144 -> 0.013979793 | H5: ='In-Sample'!H144 -> 0.0019386485 | I5: ='In-Sample'!I144 -> -0.00094015157 | J5: =AVERAGE(B17:SG17) -> 9.8897739 | K5: =J5*EXP(I5-1.96*H5) -> 9.8430082 | L5: =$J5*EXP(I5+1.96*H5) -> 9.9180951 | M5: =L5-K5 -> 0.075086914 | O5: =(B5-J5)/B5 -> 0.011022615
A6: 45787 | B6: 9.95 | C6: 37.35 | D6: -0.005 | E6: ='In-Sample'!E145 -> -0.0050125418 | F6: ='In-Sample'!F145 -> -0.0011442448 | G6: ='In-Sample'!G145 -> 0.013958987 | H6: ='In-Sample'!H145 -> 0.0019357632 | I6: ='In-Sample'!I145 -> -0.0011461183 | J6: =AVERAGE(B18:SG18) -> 9.9997823 | K6: =J6*EXP(I6-1.96*H6) -> 9.950503 | L6: =$J6*EXP(I6+1.96*H6) -> 10.026297 | M6: =L6-K6 -> 0.075793529 | O6: =(B6-J6)/B6 -> -0.0050032432
A7: 46001 | B7: 9.89 | C7: 53.41 | D7: -0.006 | E7: ='In-Sample'!E146 -> -0.0060484055 | F7: ='In-Sample'!F146 -> -0.0014418129 | G7: ='In-Sample'!G146 -> 0.013894034 | H7: ='In-Sample'!H146 -> 0.0019267559 | I7: ='In-Sample'!I146 -> -0.0014436691 | J7: =AVERAGE(B19:SG19) -> 9.9498009 | K7: =J7*EXP(I7-1.96*H7) -> 9.8979972 | L7: =$J7*EXP(I7+1.96*H7) -> 9.9730386 | M7: =L7-K7 -> 0.075041448 | O7: =(B7-J7)/B7 -> -0.0060466036
A8: 10/19/2025 | B8: 9.9 | C8: 43.01 | D8: 0.001 | E8: ='In-Sample'!E147 -> 0.0010106115 | F8: ='In-Sample'!F147 -> -0.001204669 | G8: ='In-Sample'!G147 -> 0.013827188 | H8: ='In-Sample'!H147 -> 0.001917486 | I8: ='In-Sample'!I147 -> -0.0012065073 | J8: =AVERAGE(B20:SG20) -> 9.8896944 | K8: =J8*EXP(I8-1.96*H8) -> 9.8407159 | L8: =$J8*EXP(I8+1.96*H8) -> 9.9149628 | M8: =L8-K8 -> 0.074246875 | O8: =(B8-J8)/B8 -> 0.0010409676
A9: 10/26/2025 | B9: 9.87 | C9: 47.13 | D9: -0.003 | E9: ='In-Sample'!E148 -> -0.0030349037 | F9: ='In-Sample'!F148 -> -0.0010058837 | G9: ='In-Sample'!G148 -> 0.013722748 | H9: ='In-Sample'!H148 -> 0.0019030028 | I9: ='In-Sample'!I148 -> -0.0010076944 | J9: =AVERAGE(B21:SG21) -> 9.8999354 | K9: =J9*EXP(I9-1.96*H9) -> 9.8531446 | L9: =$J9*EXP(I9+1.96*H9) -> 9.9269216 | M9: =L9-K9 -> 0.07377704 | O9: =(B9-J9)/B9 -> -0.0030329666
A10: 45699 | B10: 9.91 | C10: 56.07 | D10: 0.0041 | E10: ='In-Sample'!E149 -> 0.0040444949 | F10: ='In-Sample'!F149 -> -0.0011121329 | G10: ='In-Sample'!G149 -> 0.01366051 | H10: ='In-Sample'!H149 -> 0.0018943719 | I10: ='In-Sample'!I149 -> -0.0011139272 | J10: =AVERAGE(B22:SG22) -> 9.8697342 | K10: =J10*EXP(I10-1.96*H10) -> 9.8222088 | L10: =$J10*EXP(I10+1.96*H10) -> 9.8954194 | M10: =L10-K10 -> 0.073210606 | O10: =(B10-J10)/B10 -> 0.0040631464
A11: 45911 | B11: 9.93 | C11: 47.19 | D11: 0.002 | E11: ='In-Sample'!E150 -> 0.0020161297 | F11: ='In-Sample'!F150 -> -0.00081522613 | G11: ='In-Sample'!G150 -> 0.013555066 | H11: ='In-Sample'!H150 -> 0.0018797495 | I11: ='In-Sample'!I150 -> -0.00081699286 | J11: =AVERAGE(B23:SG23) -> 9.9098474 | K11: =J11*EXP(I11-1.96*H11) -> 9.8653405 | L11: =$J11*EXP(I11+1.96*H11) -> 9.9383029 | M11: =L11-K11 -> 0.07296241 | O11: =(B11-J11)/B11 -> 0.0020294629
A13: Forecasted Price | B13: 1 | C13: 2 | D13: 3 | E13: 4 | F13: 5 | G13: 6 | H13: 7 | I13: 8 | J13: 9 | K13: 10 | L13: 11 | M13: 12 | N13: 13 | O13: 14 | P13: 15 | Q13: 16 | R13: 17 | S13: 18 | T13: 19 | U13: 20 | V13: 21 | W13: 22 | X13: 23 | Y13: 24 | Z13: 25 | AA13: 26 | AB13: 27 | AC13: 28 | AD13: 29 | AE13: 30 | AF13: 31 | AG13: 32 | AH13: 33 | AI13: 34 | AJ13: 35 | AK13: 36 | AL13: 37 | AM13: 38 | AN13: 39 | AO13: 40 | AP13: 41 | AQ13: 42 | AR13: 43 | AS13: 44 | AT13: 45 | AU13: 46 | AV13: 47 | AW13: 48 | AX13: 49 | AY13: 50 | AZ13: 51 | BA13: 52 | BB13: 53 | BC13: 54 | BD13: 55 | BE13: 56 | BF13: 57 | BG13: 58 | BH13: 59 | BI13: 60 | BJ13: 61 | BK13: 62 | BL13: 63 | BM13: 64 | BN13: 65 | BO13: 66 | BP13: 67 | BQ13: 68 | BR13: 69 | BS13: 70 | BT13: 71 | BU13: 72 | BV13: 73 | BW13: 74 | BX13: 75 | BY13: 76 | BZ13: 77 | CA13: 78 | CB13: 79 | CC13: 80 | CD13: 81 | CE13: 82 | CF13: 83 | CG13: 84 | CH13: 85 | CI13: 86 | CJ13: 87 | CK13: 88 | CL13: 89 | CM13: 90 | CN13: 91 | CO13: 92 | CP13: 93 | CQ13: 94 | CR13: 95 | CS13: 96 | CT13: 97 | CU13: 98 | CV13: 99 | CW13: 100 | CX13: 101 | CY13: 102 | CZ13: 103 | DA13: 104 | DB13: 105 | DC13: 106 | DD13: 107 | DE13: 108 | DF13: 109 | DG13: 110 | DH13: 111 | DI13: 112 | DJ13: 113 | DK13: 114 | DL13: 115 | DM13: 116 | DN13: 117 | DO13: 118 | DP13: 119 | DQ13: 120 | DR13: 121 | DS13: 122 | DT13: 123 | DU13: 124 | DV13: 125 | DW13: 126 | DX13: 127 | DY13: 128 | DZ13: 129 | EA13: 130 | EB13: 131 | EC13: 132 | ED13: 133 | EE13: 134 | EF13: 135 | EG13: 136 | EH13: 137 | EI13: 138 | EJ13: 139 | EK13: 140 | EL13: 141 | EM13: 142 | EN13: 143 | EO13: 144 | EP13: 145 | EQ13: 146 | ER13: 147 | ES13: 148 | ET13: 149 | EU13: 150 | EV13: 151 | EW13: 152 | EX13: 153 | EY13: 154 | EZ13: 155 | FA13: 156 | FB13: 157 | FC13: 158 | FD13: 159 | FE13: 160 | FF13: 161 | FG13: 162 | FH13: 163 | FI13: 164 | FJ13: 165 | FK13: 166 | FL13: 167 | FM13: 168 | FN13: 169 | FO13: 170 | FP13: 171 | FQ13: 172 | FR13: 173 | FS13: 174 | FT13: 175 | FU13: 176 | FV13: 177 | FW13: 178 | FX13: 179 | FY13: 180 | FZ13: 181 | GA13: 182 | GB13: 183 | GC13: 184 | GD13: 185 | GE13: 186 | GF13: 187 | GG13: 188 | GH13: 189 | GI13: 190 | GJ13: 191 | GK13: 192 | GL13: 193 | GM13: 194 | GN13: 195 | GO13: 196 | GP13: 197 | GQ13: 198 | GR13: 199 | GS13: 200 | GT13: 201 | GU13: 202 | GV13: 203 | GW13: 204 | GX13: 205 | GY13: 206 | GZ13: 207 | HA13: 208 | HB13: 209 | HC13: 210 | HD13: 211 | HE13: 212 | HF13: 213 | HG13: 214 | HH13: 215 | HI13: 216 | HJ13: 217 | HK13: 218 | HL13: 219 | HM13: 220 | HN13: 221 | HO13: 222 | HP13: 223 | HQ13: 224 | HR13: 225 | HS13: 226 | HT13: 227 | HU13: 228 | HV13: 229 | HW13: 230 | HX13: 231 | HY13: 232 | HZ13: 233 | IA13: 234 | IB13: 235 | IC13: 236 | ID13: 237 | IE13: 238 | IF13: 239 | IG13: 240 | IH13: 241 | II13: 242 | IJ13: 243 | IK13: 244 | IL13: 245 | IM13: 246 | IN13: 247 | IO13: 248 | IP13: 249 | IQ13: 250 | IR13: 251 | IS13: 252 | IT13: 253 | IU13: 254 | IV13: 255 | IW13: 256 | IX13: 257 | IY13: 258 | IZ13: 259 | JA13: 260 | JB13: 261 | JC13: 262 | JD13: 263 | JE13: 264 | JF13: 265 | JG13: 266 | JH13: 267 | JI13: 268 | JJ13: 269 | JK13: 270 | JL13: 271 | JM13: 272 | JN13: 273 | JO13: 274 | JP13: 275 | JQ13: 276 | JR13: 277 | JS13: 278 | JT13: 279 | JU13: 280 | JV13: 281 | JW13: 282 | JX13: 283 | JY13: 284 | JZ13: 285 | KA13: 286 | KB13: 287 | KC13: 288 | KD13: 289 | KE13: 290 | KF13: 291 | KG13: 292 | KH13: 293 | KI13: 294 | KJ13: 295 | KK13: 296 | KL13: 297 | KM13: 298 | KN13: 299 | KO13: 300 | KP13: 301 | KQ13: 302 | KR13: 303 | KS13: 304 | KT13: 305 | KU13: 306 | KV13: 307 | KW13: 308 | KX13: 309 | KY13: 310 | KZ13: 311 | LA13: 312 | LB13: 313 | LC13: 314 | LD13: 315 | LE13: 316 | LF13: 317 | LG13: 318 | LH13: 319 | LI13: 320 | LJ13: 321 | LK13: 322 | LL13: 323 | LM13: 324 | LN13: 325 | LO13: 326 | LP13: 327 | LQ13: 328 | LR13: 329 | LS13: 330 | LT13: 331 | LU13: 332 | LV13: 333 | LW13: 334 | LX13: 335 | LY13: 336 | LZ13: 337 | MA13: 338 | MB13: 339 | MC13: 340 | MD13: 341 | ME13: 342 | MF13: 343 | MG13: 344 | MH13: 345 | MI13: 346 | MJ13: 347 | MK13: 348 | ML13: 349 | MM13: 350 | MN13: 351 | MO13: 352 | MP13: 353 | MQ13: 354 | MR13: 355 | MS13: 356 | MT13: 357 | MU13: 358 | MV13: 359 | MW13: 360 | MX13: 361 | MY13: 362 | MZ13: 363 | NA13: 364 | NB13: 365 | NC13: 366 | ND13: 367 | NE13: 368 | NF13: 369 | NG13: 370 | NH13: 371 | NI13: 372 | NJ13: 373 | NK13: 374 | NL13: 375 | NM13: 376 | NN13: 377 | NO13: 378 | NP13: 379 | NQ13: 380 | NR13: 381 | NS13: 382 | NT13: 383 | NU13: 384 | NV13: 385 | NW13: 386 | NX13: 387 | NY13: 388 | NZ13: 389 | OA13: 390 | OB13: 391 | OC13: 392 | OD13: 393 | OE13: 394 | OF13: 395 | OG13: 396 | OH13: 397 | OI13: 398 | OJ13: 399 | OK13: 400 | OL13: 401 | OM13: 402 | ON13: 403 | OO13: 404 | OP13: 405 | OQ13: 406 | OR13: 407 | OS13: 408 | OT13: 409 | OU13: 410 | OV13: 411 | OW13: 412 | OX13: 413 | OY13: 414 | OZ13: 415 | PA13: 416 | PB13: 417 | PC13: 418 | PD13: 419 | PE13: 420 | PF13: 421 | PG13: 422 | PH13: 423 | PI13: 424 | PJ13: 425 | PK13: 426 | PL13: 427 | PM13: 428 | PN13: 429 | PO13: 430 | PP13: 431 | PQ13: 432 | PR13: 433 | PS13: 434 | PT13: 435 | PU13: 436 | PV13: 437 | PW13: 438 | PX13: 439 | PY13: 440 | PZ13: 441 | QA13: 442 | QB13: 443 | QC13: 444 | QD13: 445 | QE13: 446 | QF13: 447 | QG13: 448 | QH13: 449 | QI13: 450 | QJ13: 451 | QK13: 452 | QL13: 453 | QM13: 454 | QN13: 455 | QO13: 456 | QP13: 457 | QQ13: 458 | QR13: 459 | QS13: 460 | QT13: 461 | QU13: 462 | QV13: 463 | QW13: 464 | QX13: 465 | QY13: 466 | QZ13: 467 | RA13: 468 | RB13: 469 | RC13: 470 | RD13: 471 | RE13: 472 | RF13: 473 | RG13: 474 | RH13: 475 | RI13: 476 | RJ13: 477 | RK13: 478 | RL13: 479 | RM13: 480 | RN13: 481 | RO13: 482 | RP13: 483 | RQ13: 484 | RR13: 485 | RS13: 486 | RT13: 487 | RU13: 488 | RV13: 489 | RW13: 490 | RX13: 491 | RY13: 492 | RZ13: 493 | SA13: 494 | SB13: 495 | SC13: 496 | SD13: 497 | SE13: 498 | SF13: 499 | SG13: 500
A14: 45847
A15: 09/14/2025 | B15: =$B2*EXP(($I2-($H2^2)/2)*(1/52)+$H2*SQRT(1/52)*_xlfn.NORM.INV(RAND(),0,1)) -> 9.8731697 | C15: =$B2*EXP(($I2-($H2^2)/2)*(1/52)+$H2*SQRT(1/52)*_xlfn.NORM.INV(RAND(),0,1)) -> 9.8712233 | D15: =$B2*EXP(($I2-($H2^2)/2)*(1/52)+$H2*SQRT(1/52)*_xlfn.NORM.INV(RAND(),0,1)) -> 9.8711224 | E15: =$B2*EXP(($I2-($H2^2)/2)*(1/52)+$H2*SQRT(1/52)*_xlfn.NORM.INV(RAND(),0,1)) -> 9.8683708 | F15: =$B2*EXP(($I2-($H2^2)/2)*(1/52)+$H2*SQRT(1/52)*_xlfn.NORM.INV(RAND(),0,1)) -> 9.869294 | G15: =$B2*EXP(($I2-($H2^2)/2)*(1/52)+$H2*SQRT(1/52)*_xlfn.NORM.INV(RAND(),0,1)) -> 9.8728067 | H15: =$B2*EXP(($I2-($H2^2)/2)*(1/52)+$H2*SQRT(1/52)*_xlfn.NORM.INV(RAND(),0,1)) -> 9.8657939 | I15: =$B2*EXP(($I2-($H2^2)/2)*(1/52)+$H2*SQRT(1/52)*_xlfn.NORM.INV(RAND(),0,1)) -> 9.8691764 | ... SG15: =$B2*EXP(($I2-($H2^2)/2)*(1/52)+$H2*SQRT(1/52)*_xlfn.NORM.INV(RAND(),0,1)) -> 9.8683674
A16: 09/21/2025 | B16: =$B3*EXP(($I3-($H3^2)/2)*(1/52)+$H3*SQRT(1/52)*_xlfn.NORM.INV(RAND(),0,1)) -> 9.7996897 | C16: =$B3*EXP(($I3-($H3^2)/2)*(1/52)+$H3*SQRT(1/52)*_xlfn.NORM.INV(RAND(),0,1)) -> 9.8015359 | D16: =$B3*EXP(($I3-($H3^2)/2)*(1/52)+$H3*SQRT(1/52)*_xlfn.NORM.INV(RAND(),0,1)) -> 9.7978547 | E16: =$B3*EXP(($I3-($H3^2)/2)*(1/52)+$H3*SQRT(1/52)*_xlfn.NORM.INV(RAND(),0,1)) -> 9.7994682 | F16: =$B3*EXP(($I3-($H3^2)/2)*(1/52)+$H3*SQRT(1/52)*_xlfn.NORM.INV(RAND(),0,1)) -> 9.7990422 | G16: =$B3*EXP(($I3-($H3^2)/2)*(1/52)+$H3*SQRT(1/52)*_xlfn.NORM.INV(RAND(),0,1)) -> 9.803268 | H16: =$B3*EXP(($I3-($H3^2)/2)*(1/52)+$H3*SQRT(1/52)*_xlfn.NORM.INV(RAND(),0,1)) -> 9.8017614 | I16: =$B3*EXP(($I3-($H3^2)/2)*(1/52)+$H3*SQRT(1/52)*_xlfn.NORM.INV(RAND(),0,1)) -> 9.8006766 | ... SG16: =$B3*EXP(($I3-($H3^2)/2)*(1/52)+$H3*SQRT(1/52)*_xlfn.NORM.INV(RAND(),0,1)) -> 9.8007954
A17: 09/28/2025 | B17: =$B4*EXP(($I4-($H4^2)/2)*(1/52)+$H4*SQRT(1/52)*_xlfn.NORM.INV(RAND(),0,1)) -> 9.8865714 | C17: =$B4*EXP(($I4-($H4^2)/2)*(1/52)+$H4*SQRT(1/52)*_xlfn.NORM.INV(RAND(),0,1)) -> 9.8926306 | D17: =$B4*EXP(($I4-($H4^2)/2)*(1/52)+$H4*SQRT(1/52)*_xlfn.NORM.INV(RAND(),0,1)) -> 9.8951864 | E17: =$B4*EXP(($I4-($H4^2)/2)*(1/52)+$H4*SQRT(1/52)*_xlfn.NORM.INV(RAND(),0,1)) -> 9.8917228 | F17: =$B4*EXP(($I4-($H4^2)/2)*(1/52)+$H4*SQRT(1/52)*_xlfn.NORM.INV(RAND(),0,1)) -> 9.8891791 | G17: =$B4*EXP(($I4-($H4^2)/2)*(1/52)+$H4*SQRT(1/52)*_xlfn.NORM.INV(RAND(),0,1)) -> 9.8903902 | H17: =$B4*EXP(($I4-($H4^2)/2)*(1/52)+$H4*SQRT(1/52)*_xlfn.NORM.INV(RAND(),0,1)) -> 9.8923312 | I17: =$B4*EXP(($I4-($H4^2)/2)*(1/52)+$H4*SQRT(1/52)*_xlfn.NORM.INV(RAND(),0,1)) -> 9.8890909 | ... SG17: =$B4*EXP(($I4-($H4^2)/2)*(1/52)+$H4*SQRT(1/52)*_xlfn.NORM.INV(RAND(),0,1)) -> 9.8932173
A18: 45787 | B18: =$B5*EXP(($I5-($H5^2)/2)*(1/52)+$H5*SQRT(1/52)*_xlfn.NORM.INV(RAND(),0,1)) -> 9.9949036 | C18: =$B5*EXP(($I5-($H5^2)/2)*(1/52)+$H5*SQRT(1/52)*_xlfn.NORM.INV(RAND(),0,1)) -> 10.002176 | D18: =$B5*EXP(($I5-($H5^2)/2)*(1/52)+$H5*SQRT(1/52)*_xlfn.NORM.INV(RAND(),0,1)) -> 10.003365 | E18: =$B5*EXP(($I5-($H5^2)/2)*(1/52)+$H5*SQRT(1/52)*_xlfn.NORM.INV(RAND(),0,1)) -> 10.004799 | F18: =$B5*EXP(($I5-($H5^2)/2)*(1/52)+$H5*SQRT(1/52)*_xlfn.NORM.INV(RAND(),0,1)) -> 10.002347 | G18: =$B5*EXP(($I5-($H5^2)/2)*(1/52)+$H5*SQRT(1/52)*_xlfn.NORM.INV(RAND(),0,1)) -> 10.000921 | H18: =$B5*EXP(($I5-($H5^2)/2)*(1/52)+$H5*SQRT(1/52)*_xlfn.NORM.INV(RAND(),0,1)) -> 9.9968964 | I18: =$B5*EXP(($I5-($H5^2)/2)*(1/52)+$H5*SQRT(1/52)*_xlfn.NORM.INV(RAND(),0,1)) -> 10.005922 | ... SG18: =$B5*EXP(($I5-($H5^2)/2)*(1/52)+$H5*SQRT(1/52)*_xlfn.NORM.INV(RAND(),0,1)) -> 9.9989832
A19: 46001 | B19: =$B6*EXP(($I6-($H6^2)/2)*(1/52)+$H6*SQRT(1/52)*_xlfn.NORM.INV(RAND(),0,1)) -> 9.9524515 | C19: =$B6*EXP(($I6-($H6^2)/2)*(1/52)+$H6*SQRT(1/52)*_xlfn.NORM.INV(RAND(),0,1)) -> 9.9495997 | D19: =$B6*EXP(($I6-($H6^2)/2)*(1/52)+$H6*SQRT(1/52)*_xlfn.NORM.INV(RAND(),0,1)) -> 9.9488322 | E19: =$B6*EXP(($I6-($H6^2)/2)*(1/52)+$H6*SQRT(1/52)*_xlfn.NORM.INV(RAND(),0,1)) -> 9.9518878 | F19: =$B6*EXP(($I6-($H6^2)/2)*(1/52)+$H6*SQRT(1/52)*_xlfn.NORM.INV(RAND(),0,1)) -> 9.9474748 | G19: =$B6*EXP(($I6-($H6^2)/2)*(1/52)+$H6*SQRT(1/52)*_xlfn.NORM.INV(RAND(),0,1)) -> 9.9520307 | H19: =$B6*EXP(($I6-($H6^2)/2)*(1/52)+$H6*SQRT(1/52)*_xlfn.NORM.INV(RAND(),0,1)) -> 9.9497022 | I19: =$B6*EXP(($I6-($H6^2)/2)*(1/52)+$H6*SQRT(1/52)*_xlfn.NORM.INV(RAND(),0,1)) -> 9.9480211 | ... SG19: =$B6*EXP(($I6-($H6^2)/2)*(1/52)+$H6*SQRT(1/52)*_xlfn.NORM.INV(RAND(),0,1)) -> 9.9549216
A20: 10/19/2025 | B20: =$B7*EXP(($I7-($H7^2)/2)*(1/52)+$H7*SQRT(1/52)*_xlfn.NORM.INV(RAND(),0,1)) -> 9.8895022 | C20: =$B7*EXP(($I7-($H7^2)/2)*(1/52)+$H7*SQRT(1/52)*_xlfn.NORM.INV(RAND(),0,1)) -> 9.8905877 | D20: =$B7*EXP(($I7-($H7^2)/2)*(1/52)+$H7*SQRT(1/52)*_xlfn.NORM.INV(RAND(),0,1)) -> 9.8867303 | E20: =$B7*EXP(($I7-($H7^2)/2)*(1/52)+$H7*SQRT(1/52)*_xlfn.NORM.INV(RAND(),0,1)) -> 9.8916581 | F20: =$B7*EXP(($I7-($H7^2)/2)*(1/52)+$H7*SQRT(1/52)*_xlfn.NORM.INV(RAND(),0,1)) -> 9.8882103 | G20: =$B7*EXP(($I7-($H7^2)/2)*(1/52)+$H7*SQRT(1/52)*_xlfn.NORM.INV(RAND(),0,1)) -> 9.887474 | H20: =$B7*EXP(($I7-($H7^2)/2)*(1/52)+$H7*SQRT(1/52)*_xlfn.NORM.INV(RAND(),0,1)) -> 9.8936305 | I20: =$B7*EXP(($I7-($H7^2)/2)*(1/52)+$H7*SQRT(1/52)*_xlfn.NORM.INV(RAND(),0,1)) -> 9.8903494 | ... SG20: =$B7*EXP(($I7-($H7^2)/2)*(1/52)+$H7*SQRT(1/52)*_xlfn.NORM.INV(RAND(),0,1)) -> 9.892335
A21: 10/26/2025 | B21: =$B8*EXP(($I8-($H8^2)/2)*(1/52)+$H8*SQRT(1/52)*_xlfn.NORM.INV(RAND(),0,1)) -> 9.9013261 | C21: =$B8*EXP(($I8-($H8^2)/2)*(1/52)+$H8*SQRT(1/52)*_xlfn.NORM.INV(RAND(),0,1)) -> 9.9054243 | D21: =$B8*EXP(($I8-($H8^2)/2)*(1/52)+$H8*SQRT(1/52)*_xlfn.NORM.INV(RAND(),0,1)) -> 9.9000678 | E21: =$B8*EXP(($I8-($H8^2)/2)*(1/52)+$H8*SQRT(1/52)*_xlfn.NORM.INV(RAND(),0,1)) -> 9.8992733 | F21: =$B8*EXP(($I8-($H8^2)/2)*(1/52)+$H8*SQRT(1/52)*_xlfn.NORM.INV(RAND(),0,1)) -> 9.9001571 | G21: =$B8*EXP(($I8-($H8^2)/2)*(1/52)+$H8*SQRT(1/52)*_xlfn.NORM.INV(RAND(),0,1)) -> 9.9004691 | H21: =$B8*EXP(($I8-($H8^2)/2)*(1/52)+$H8*SQRT(1/52)*_xlfn.NORM.INV(RAND(),0,1)) -> 9.899149 | I21: =$B8*EXP(($I8-($H8^2)/2)*(1/52)+$H8*SQRT(1/52)*_xlfn.NORM.INV(RAND(),0,1)) -> 9.9018429 | ... SG21: =$B8*EXP(($I8-($H8^2)/2)*(1/52)+$H8*SQRT(1/52)*_xlfn.NORM.INV(RAND(),0,1)) -> 9.9001564
A22: 45699 | B22: =$B9*EXP(($I9-($H9^2)/2)*(1/52)+$H9*SQRT(1/52)*_xlfn.NORM.INV(RAND(),0,1)) -> 9.869944 | C22: =$B9*EXP(($I9-($H9^2)/2)*(1/52)+$H9*SQRT(1/52)*_xlfn.NORM.INV(RAND(),0,1)) -> 9.8752929 | D22: =$B9*EXP(($I9-($H9^2)/2)*(1/52)+$H9*SQRT(1/52)*_xlfn.NORM.INV(RAND(),0,1)) -> 9.8723209 | E22: =$B9*EXP(($I9-($H9^2)/2)*(1/52)+$H9*SQRT(1/52)*_xlfn.NORM.INV(RAND(),0,1)) -> 9.8683706 | F22: =$B9*EXP(($I9-($H9^2)/2)*(1/52)+$H9*SQRT(1/52)*_xlfn.NORM.INV(RAND(),0,1)) -> 9.8649847 | G22: =$B9*EXP(($I9-($H9^2)/2)*(1/52)+$H9*SQRT(1/52)*_xlfn.NORM.INV(RAND(),0,1)) -> 9.8651024 | H22: =$B9*EXP(($I9-($H9^2)/2)*(1/52)+$H9*SQRT(1/52)*_xlfn.NORM.INV(RAND(),0,1)) -> 9.8686116 | I22: =$B9*EXP(($I9-($H9^2)/2)*(1/52)+$H9*SQRT(1/52)*_xlfn.NORM.INV(RAND(),0,1)) -> 9.8694102 | ... SG22: =$B9*EXP(($I9-($H9^2)/2)*(1/52)+$H9*SQRT(1/52)*_xlfn.NORM.INV(RAND(),0,1)) -> 9.8766137
A23: 45911 | B23: =$B10*EXP(($I10-($H10^2)/2)*(1/52)+$H10*SQRT(1/52)*_xlfn.NORM.INV(RAND(),0,1)) -> 9.9089151 | C23: =$B10*EXP(($I10-($H10^2)/2)*(1/52)+$H10*SQRT(1/52)*_xlfn.NORM.INV(RAND(),0,1)) -> 9.915513 | D23: =$B10*EXP(($I10-($H10^2)/2)*(1/52)+$H10*SQRT(1/52)*_xlfn.NORM.INV(RAND(),0,1)) -> 9.9095162 | E23: =$B10*EXP(($I10-($H10^2)/2)*(1/52)+$H10*SQRT(1/52)*_xlfn.NORM.INV(RAND(),0,1)) -> 9.911629 | F23: =$B10*EXP(($I10-($H10^2)/2)*(1/52)+$H10*SQRT(1/52)*_xlfn.NORM.INV(RAND(),0,1)) -> 9.9090973 | G23: =$B10*EXP(($I10-($H10^2)/2)*(1/52)+$H10*SQRT(1/52)*_xlfn.NORM.INV(RAND(),0,1)) -> 9.9083446 | H23: =$B10*EXP(($I10-($H10^2)/2)*(1/52)+$H10*SQRT(1/52)*_xlfn.NORM.INV(RAND(),0,1)) -> 9.9117775 | I23: =$B10*EXP(($I10-($H10^2)/2)*(1/52)+$H10*SQRT(1/52)*_xlfn.NORM.INV(RAND(),0,1)) -> 9.9116448 | ... SG23: =$B10*EXP(($I10-($H10^2)/2)*(1/52)+$H10*SQRT(1/52)*_xlfn.NORM.INV(RAND(),0,1)) -> 9.910001

Sheet Out Sample Forecast (Dividend)
A1: Date | B1: Price | C1: Vol. (M) | D1: Change % | E1: Weekly Log Return | F1: Raw Drift | G1: Volatility | H1: Annualised Volatility | I1: Market Drift | J1: Dividend Yield, q | K1: Forecasted Price (Mean) | L1: Percentage Error | M1: MPE | O1: Dividend
A2: 45847 | B2: 9.87 | C2: 56.57 | D2: -0.012 | E2: ='In-Sample'!E141 -> -0.012084739 | F2: ='In-Sample'!F141 -> -0.0014446275 | G2: ='In-Sample'!G141 -> 0.013827992 | H2: ='In-Sample'!H141 -> 0.0019175974 | I2: ='In-Sample'!I141 -> -0.0014464661 | M2: =AVERAGE(L3:L11) -> 0.001848666 | O2: 0.6
A3: 09/14/2025 | B3: 9.8 | C3: 33.54 | D3: -0.0071 | E3: ='In-Sample'!E142 -> -0.0071174678 | F3: ='In-Sample'!F142 -> -0.0015090695 | G3: ='In-Sample'!G142 -> 0.01384682 | H3: ='In-Sample'!H142 -> 0.0019202084 | I3: ='In-Sample'!I142 -> -0.0015109131 | J3: =$O$2/B2 -> 0.060790274 | K3: =AVERAGE(B15:SG15) -> 9.8581625 | L3: =(B3-K3)/B3 -> -0.0059349458
A4: 09/21/2025 | B4: 9.89 | C4: 50.26 | D4: 0.0092 | E4: ='In-Sample'!E143 -> 0.00914176 | F4: ='In-Sample'!F143 -> -0.0011509829 | G4: ='In-Sample'!G143 -> 0.013877413 | H4: ='In-Sample'!H143 -> 0.0019244509 | I4: ='In-Sample'!I143 -> -0.0011528347 | J4: =$O$2/B3 -> 0.06122449 | K4: =AVERAGE(B16:SG16) -> 9.788254 | L4: =(B4-K4)/B4 -> 0.01028777
A5: 09/28/2025 | B5: 10 | C5: 54.95 | D5: 0.0111 | E5: ='In-Sample'!E144 -> 0.011060947 | F5: ='In-Sample'!F144 -> -0.00093827239 | G5: ='In-Sample'!G144 -> 0.013979793 | H5: ='In-Sample'!H144 -> 0.0019386485 | I5: ='In-Sample'!I144 -> -0.00094015157 | J5: =$O$2/B4 -> 0.060667341 | K5: =AVERAGE(B17:SG17) -> 9.8781999 | L5: =(B5-K5)/B5 -> 0.012180015
A6: 45787 | B6: 9.95 | C6: 37.35 | D6: -0.005 | E6: ='In-Sample'!E145 -> -0.0050125418 | F6: ='In-Sample'!F145 -> -0.0011442448 | G6: ='In-Sample'!G145 -> 0.013958987 | H6: ='In-Sample'!H145 -> 0.0019357632 | I6: ='In-Sample'!I145 -> -0.0011461183 | J6: =$O$2/B5 -> 0.06 | K6: =AVERAGE(B18:SG18) -> 9.9880983 | L6: =(B6-K6)/B6 -> -0.0038289781
A7: 46001 | B7: 9.89 | C7: 53.41 | D7: -0.006 | E7: ='In-Sample'!E146 -> -0.0060484055 | F7: ='In-Sample'!F146 -> -0.0014418129 | G7: ='In-Sample'!G146 -> 0.013894034 | H7: ='In-Sample'!H146 -> 0.0019267559 | I7: ='In-Sample'!I146 -> -0.0014436691 | J7: =$O$2/B6 -> 0.060301508 | K7: =AVERAGE(B19:SG19) -> 9.9381108 | L7: =(B7-K7)/B7 -> -0.0048645918
A8: 10/19/2025 | B8: 9.9 | C8: 43.01 | D8: 0.001 | E8: ='In-Sample'!E147 -> 0.0010106115 | F8: ='In-Sample'!F147 -> -0.001204669 | G8: ='In-Sample'!G147 -> 0.013827188 | H8: ='In-Sample'!H147 -> 0.001917486 | I8: ='In-Sample'!I147 -> -0.0012065073 | J8: =$O$2/B7 -> 0.060667341 | K8: =AVERAGE(B20:SG20) -> 9.8781083 | L8: =(B8-K8)/B8 -> 0.0022112835
A9: 10/26/2025 | B9: 9.87 | C9: 47.13 | D9: -0.003 | E9: ='In-Sample'!E148 -> -0.0030349037 | F9: ='In-Sample'!F148 -> -0.0010058837 | G9: ='In-Sample'!G148 -> 0.013722748 | H9: ='In-Sample'!H148 -> 0.0019030028 | I9: ='In-Sample'!I148 -> -0.0010076944 | J9: =$O$2/B8 -> 0.060606061 | K9: =AVERAGE(B21:SG21) -> 9.8882031 | L9: =(B9-K9)/B9 -> -0.0018442841
A10: 45699 | B10: 9.91 | C10: 56.07 | D10: 0.0041 | E10: ='In-Sample'!E149 -> 0.0040444949 | F10: ='In-Sample'!F149 -> -0.0011121329 | G10: ='In-Sample'!G149 -> 0.01366051 | H10: ='In-Sample'!H149 -> 0.0018943719 | I10: ='In-Sample'!I149 -> -0.0011139272 | J10: =$O$2/B9 -> 0.060790274 | K10: =AVERAGE(B22:SG22) -> 9.858239 | L10: =(B10-K10)/B10 -> 0.0052231045
A11: 45911 | B11: 9.93 | C11: 47.19 | D11: 0.002 | E11: ='In-Sample'!E150 -> 0.0020161297 | F11: ='In-Sample'!F150 -> -0.00081522613 | G11: ='In-Sample'!G150 -> 0.013555066 | H11: ='In-Sample'!H150 -> 0.0018797495 | I11: ='In-Sample'!I150 -> -0.00081699286 | J11: =$O$2/B10 -> 0.060544904 | K11: =AVERAGE(B23:SG23) -> 9.8981384 | L11: =(B11-K11)/B11 -> 0.003208621
A13: Forecasted Price | B13: 1 | C13: 2 | D13: 3 | E13: 4 | F13: 5 | G13: 6 | H13: 7 | I13: 8 | J13: 9 | K13: 10 | L13: 11 | M13: 12 | N13: 13 | O13: 14 | P13: 15 | Q13: 16 | R13: 17 | S13: 18 | T13: 19 | U13: 20 | V13: 21 | W13: 22 | X13: 23 | Y13: 24 | Z13: 25 | AA13: 26 | AB13: 27 | AC13: 28 | AD13: 29 | AE13: 30 | AF13: 31 | AG13: 32 | AH13: 33 | AI13: 34 | AJ13: 35 | AK13: 36 | AL13: 37 | AM13: 38 | AN13: 39 | AO13: 40 | AP13: 41 | AQ13: 42 | AR13: 43 | AS13: 44 | AT13: 45 | AU13: 46 | AV13: 47 | AW13: 48 | AX13: 49 | AY13: 50 | AZ13: 51 | BA13: 52 | BB13: 53 | BC13: 54 | BD13: 55 | BE13: 56 | BF13: 57 | BG13: 58 | BH13: 59 | BI13: 60 | BJ13: 61 | BK13: 62 | BL13: 63 | BM13: 64 | BN13: 65 | BO13: 66 | BP13: 67 | BQ13: 68 | BR13: 69 | BS13: 70 | BT13: 71 | BU13: 72 | BV13: 73 | BW13: 74 | BX13: 75 | BY13: 76 | BZ13: 77 | CA13: 78 | CB13: 79 | CC13: 80 | CD13: 81 | CE13: 82 | CF13: 83 | CG13: 84 | CH13: 85 | CI13: 86 | CJ13: 87 | CK13: 88 | CL13: 89 | CM13: 90 | CN13: 91 | CO13: 92 | CP13: 93 | CQ13: 94 | CR13: 95 | CS13: 96 | CT13: 97 | CU13: 98 | CV13: 99 | CW13: 100 | CX13: 101 | CY13: 102 | CZ13: 103 | DA13: 104 | DB13: 105 | DC13: 106 | DD13: 107 | DE13: 108 | DF13: 109 | DG13: 110 | DH13: 111 | DI13: 112 | DJ13: 113 | DK13: 114 | DL13: 115 | DM13: 116 | DN13: 117 | DO13: 118 | DP13: 119 | DQ13: 120 | DR13: 121 | DS13: 122 | DT13: 123 | DU13: 124 | DV13: 125 | DW13: 126 | DX13: 127 | DY13: 128 | DZ13: 129 | EA13: 130 | EB13: 131 | EC13: 132 | ED13: 133 | EE13: 134 | EF13: 135 | EG13: 136 | EH13: 137 | EI13: 138 | EJ13: 139 | EK13: 140 | EL13: 141 | EM13: 142 | EN13: 143 | EO13: 144 | EP13: 145 | EQ13: 146 | ER13: 147 | ES13: 148 | ET13: 149 | EU13: 150 | EV13: 151 | EW13: 152 | EX13: 153 | EY13: 154 | EZ13: 155 | FA13: 156 | FB13: 157 | FC13: 158 | FD13: 159 | FE13: 160 | FF13: 161 | FG13: 162 | FH13: 163 | FI13: 164 | FJ13: 165 | FK13: 166 | FL13: 167 | FM13: 168 | FN13: 169 | FO13: 170 | FP13: 171 | FQ13: 172 | FR13: 173 | FS13: 174 | FT13: 175 | FU13: 176 | FV13: 177 | FW13: 178 | FX13: 179 | FY13: 180 | FZ13: 181 | GA13: 182 | GB13: 183 | GC13: 184 | GD13: 185 | GE13: 186 | GF13: 187 | GG13: 188 | GH13: 189 | GI13: 190 | GJ13: 191 | GK13: 192 | GL13: 193 | GM13: 194 | GN13: 195 | GO13: 196 | GP13: 197 | GQ13: 198 | GR13: 199 | GS13: 200 | GT13: 201 | GU13: 202 | GV13: 203 | GW13: 204 | GX13: 205 | GY13: 206 | GZ13: 207 | HA13: 208 | HB13: 209 | HC13: 210 | HD13: 211 | HE13: 212 | HF13: 213 | HG13: 214 | HH13: 215 | HI13: 216 | HJ13: 217 | HK13: 218 | HL13: 219 | HM13: 220 | HN13: 221 | HO13: 222 | HP13: 223 | HQ13: 224 | HR13: 225 | HS13: 226 | HT13: 227 | HU13: 228 | HV13: 229 | HW13: 230 | HX13: 231 | HY13: 232 | HZ13: 233 | IA13: 234 | IB13: 235 | IC13: 236 | ID13: 237 | IE13: 238 | IF13: 239 | IG13: 240 | IH13: 241 | II13: 242 | IJ13: 243 | IK13: 244 | IL13: 245 | IM13: 246 | IN13: 247 | IO13: 248 | IP13: 249 | IQ13: 250 | IR13: 251 | IS13: 252 | IT13: 253 | IU13: 254 | IV13: 255 | IW13: 256 | IX13: 257 | IY13: 258 | IZ13: 259 | JA13: 260 | JB13: 261 | JC13: 262 | JD13: 263 | JE13: 264 | JF13: 265 | JG13: 266 | JH13: 267 | JI13: 268 | JJ13: 269 | JK13: 270 | JL13: 271 | JM13: 272 | JN13: 273 | JO13: 274 | JP13: 275 | JQ13: 276 | JR13: 277 | JS13: 278 | JT13: 279 | JU13: 280 | JV13: 281 | JW13: 282 | JX13: 283 | JY13: 284 | JZ13: 285 | KA13: 286 | KB13: 287 | KC13: 288 | KD13: 289 | KE13: 290 | KF13: 291 | KG13: 292 | KH13: 293 | KI13: 294 | KJ13: 295 | KK13: 296 | KL13: 297 | KM13: 298 | KN13: 299 | KO13: 300 | KP13: 301 | KQ13: 302 | KR13: 303 | KS13: 304 | KT13: 305 | KU13: 306 | KV13: 307 | KW13: 308 | KX13: 309 | KY13: 310 | KZ13: 311 | LA13: 312 | LB13: 313 | LC13: 314 | LD13: 315 | LE13: 316 | LF13: 317 | LG13: 318 | LH13: 319 | LI13: 320 | LJ13: 321 | LK13: 322 | LL13: 323 | LM13: 324 | LN13: 325 | LO13: 326 | LP13: 327 | LQ13: 328 | LR13: 329 | LS13: 330 | LT13: 331 | LU13: 332 | LV13: 333 | LW13: 334 | LX13: 335 | LY13: 336 | LZ13: 337 | MA13: 338 | MB13: 339 | MC13: 340 | MD13: 341 | ME13: 342 | MF13: 343 | MG13: 344 | MH13: 345 | MI13: 346 | MJ13: 347 | MK13: 348 | ML13: 349 | MM13: 350 | MN13: 351 | MO13: 352 | MP13: 353 | MQ13: 354 | MR13: 355 | MS13: 356 | MT13: 357 | MU13: 358 | MV13: 359 | MW13: 360 | MX13: 361 | MY13: 362 | MZ13: 363 | NA13: 364 | NB13: 365 | NC13: 366 | ND13: 367 | NE13: 368 | NF13: 369 | NG13: 370 | NH13: 371 | NI13: 372 | NJ13: 373 | NK13: 374 | NL13: 375 | NM13: 376 | NN13: 377 | NO13: 378 | NP13: 379 | NQ13: 380 | NR13: 381 | NS13: 382 | NT13: 383 | NU13: 384 | NV13: 385 | NW13: 386 | NX13: 387 | NY13: 388 | NZ13: 389 | OA13: 390 | OB13: 391 | OC13: 392 | OD13: 393 | OE13: 394 | OF13: 395 | OG13: 396 | OH13: 397 | OI13: 398 | OJ13: 399 | OK13: 400 | OL13: 401 | OM13: 402 | ON13: 403 | OO13: 404 | OP13: 405 | OQ13: 406 | OR13: 407 | OS13: 408 | OT13: 409 | OU13: 410 | OV13: 411 | OW13: 412 | OX13: 413 | OY13: 414 | OZ13: 415 | PA13: 416 | PB13: 417 | PC13: 418 | PD13: 419 | PE13: 420 | PF13: 421 | PG13: 422 | PH13: 423 | PI13: 424 | PJ13: 425 | PK13: 426 | PL13: 427 | PM13: 428 | PN13: 429 | PO13: 430 | PP13: 431 | PQ13: 432 | PR13: 433 | PS13: 434 | PT13: 435 | PU13: 436 | PV13: 437 | PW13: 438 | PX13: 439 | PY13: 440 | PZ13: 441 | QA13: 442 | QB13: 443 | QC13: 444 | QD13: 445 | QE13: 446 | QF13: 447 | QG13: 448 | QH13: 449 | QI13: 450 | QJ13: 451 | QK13: 452 | QL13: 453 | QM13: 454 | QN13: 455 | QO13: 456 | QP13: 457 | QQ13: 458 | QR13: 459 | QS13: 460 | QT13: 461 | QU13: 462 | QV13: 463 | QW13: 464 | QX13: 465 | QY13: 466 | QZ13: 467 | RA13: 468 | RB13: 469 | RC13: 470 | RD13: 471 | RE13: 472 | RF13: 473 | RG13: 474 | RH13: 475 | RI13: 476 | RJ13: 477 | RK13: 478 | RL13: 479 | RM13: 480 | RN13: 481 | RO13: 482 | RP13: 483 | RQ13: 484 | RR13: 485 | RS13: 486 | RT13: 487 | RU13: 488 | RV13: 489 | RW13: 490 | RX13: 491 | RY13: 492 | RZ13: 493 | SA13: 494 | SB13: 495 | SC13: 496 | SD13: 497 | SE13: 498 | SF13: 499 | SG13: 500
A14: 45847
A15: 09/14/2025 | B15: =$B2*EXP(($I2-$J3-($H2^2)/2)*(1/52)+$H2*SQRT(1/52)*_xlfn.NORM.INV(RAND(),0,1)) -> 9.8596191 | C15: =$B2*EXP(($I2-$J3-($H2^2)/2)*(1/52)+$H2*SQRT(1/52)*_xlfn.NORM.INV(RAND(),0,1)) -> 9.8546181 | D15: =$B2*EXP(($I2-$J3-($H2^2)/2)*(1/52)+$H2*SQRT(1/52)*_xlfn.NORM.INV(RAND(),0,1)) -> 9.8574836 | E15: =$B2*EXP(($I2-$J3-($H2^2)/2)*(1/52)+$H2*SQRT(1/52)*_xlfn.NORM.INV(RAND(),0,1)) -> 9.859491 | F15: =$B2*EXP(($I2-$J3-($H2^2)/2)*(1/52)+$H2*SQRT(1/52)*_xlfn.NORM.INV(RAND(),0,1)) -> 9.8600643 | G15: =$B2*EXP(($I2-$J3-($H2^2)/2)*(1/52)+$H2*SQRT(1/52)*_xlfn.NORM.INV(RAND(),0,1)) -> 9.8571709 | H15: =$B2*EXP(($I2-$J3-($H2^2)/2)*(1/52)+$H2*SQRT(1/52)*_xlfn.NORM.INV(RAND(),0,1)) -> 9.8593969 | I15: =$B2*EXP(($I2-$J3-($H2^2)/2)*(1/52)+$H2*SQRT(1/52)*_xlfn.NORM.INV(RAND(),0,1)) -> 9.8614111 | ... SG15: =$B2*EXP(($I2-$J3-($H2^2)/2)*(1/52)+$H2*SQRT(1/52)*_xlfn.NORM.INV(RAND(),0,1)) -> 9.8582988
A16: 09/21/2025 | B16: =$B3*EXP(($I3-$J4-($H3^2)/2)*(1/52)+$H3*SQRT(1/52)*_xlfn.NORM.INV(RAND(),0,1)) -> 9.7930786 | C16: =$B3*EXP(($I3-$J4-($H3^2)/2)*(1/52)+$H3*SQRT(1/52)*_xlfn.NORM.INV(RAND(),0,1)) -> 9.7889464 | D16: =$B3*EXP(($I3-$J4-($H3^2)/2)*(1/52)+$H3*SQRT(1/52)*_xlfn.NORM.INV(RAND(),0,1)) -> 9.7878586 | E16: =$B3*EXP(($I3-$J4-($H3^2)/2)*(1/52)+$H3*SQRT(1/52)*_xlfn.NORM.INV(RAND(),0,1)) -> 9.7887107 | F16: =$B3*EXP(($I3-$J4-($H3^2)/2)*(1/52)+$H3*SQRT(1/52)*_xlfn.NORM.INV(RAND(),0,1)) -> 9.7906991 | G16: =$B3*EXP(($I3-$J4-($H3^2)/2)*(1/52)+$H3*SQRT(1/52)*_xlfn.NORM.INV(RAND(),0,1)) -> 9.7888667 | H16: =$B3*EXP(($I3-$J4-($H3^2)/2)*(1/52)+$H3*SQRT(1/52)*_xlfn.NORM.INV(RAND(),0,1)) -> 9.7889501 | I16: =$B3*EXP(($I3-$J4-($H3^2)/2)*(1/52)+$H3*SQRT(1/52)*_xlfn.NORM.INV(RAND(),0,1)) -> 9.786651 | ... SG16: =$B3*EXP(($I3-$J4-($H3^2)/2)*(1/52)+$H3*SQRT(1/52)*_xlfn.NORM.INV(RAND(),0,1)) -> 9.7894149
A17: 09/28/2025 | B17: =$B4*EXP(($I4-$J5-($H4^2)/2)*(1/52)+$H4*SQRT(1/52)*_xlfn.NORM.INV(RAND(),0,1)) -> 9.8807622 | C17: =$B4*EXP(($I4-$J5-($H4^2)/2)*(1/52)+$H4*SQRT(1/52)*_xlfn.NORM.INV(RAND(),0,1)) -> 9.8798171 | D17: =$B4*EXP(($I4-$J5-($H4^2)/2)*(1/52)+$H4*SQRT(1/52)*_xlfn.NORM.INV(RAND(),0,1)) -> 9.8810465 | E17: =$B4*EXP(($I4-$J5-($H4^2)/2)*(1/52)+$H4*SQRT(1/52)*_xlfn.NORM.INV(RAND(),0,1)) -> 9.876715 | F17: =$B4*EXP(($I4-$J5-($H4^2)/2)*(1/52)+$H4*SQRT(1/52)*_xlfn.NORM.INV(RAND(),0,1)) -> 9.8729802 | G17: =$B4*EXP(($I4-$J5-($H4^2)/2)*(1/52)+$H4*SQRT(1/52)*_xlfn.NORM.INV(RAND(),0,1)) -> 9.8746041 | H17: =$B4*EXP(($I4-$J5-($H4^2)/2)*(1/52)+$H4*SQRT(1/52)*_xlfn.NORM.INV(RAND(),0,1)) -> 9.8745495 | I17: =$B4*EXP(($I4-$J5-($H4^2)/2)*(1/52)+$H4*SQRT(1/52)*_xlfn.NORM.INV(RAND(),0,1)) -> 9.871645 | ... SG17: =$B4*EXP(($I4-$J5-($H4^2)/2)*(1/52)+$H4*SQRT(1/52)*_xlfn.NORM.INV(RAND(),0,1)) -> 9.8784696
A18: 45787 | B18: =$B5*EXP(($I5-$J6-($H5^2)/2)*(1/52)+$H5*SQRT(1/52)*_xlfn.NORM.INV(RAND(),0,1)) -> 9.9829868 | C18: =$B5*EXP(($I5-$J6-($H5^2)/2)*(1/52)+$H5*SQRT(1/52)*_xlfn.NORM.INV(RAND(),0,1)) -> 9.9869467 | D18: =$B5*EXP(($I5-$J6-($H5^2)/2)*(1/52)+$H5*SQRT(1/52)*_xlfn.NORM.INV(RAND(),0,1)) -> 9.9903013 | E18: =$B5*EXP(($I5-$J6-($H5^2)/2)*(1/52)+$H5*SQRT(1/52)*_xlfn.NORM.INV(RAND(),0,1)) -> 9.9886972 | F18: =$B5*EXP(($I5-$J6-($H5^2)/2)*(1/52)+$H5*SQRT(1/52)*_xlfn.NORM.INV(RAND(),0,1)) -> 9.9878764 | G18: =$B5*EXP(($I5-$J6-($H5^2)/2)*(1/52)+$H5*SQRT(1/52)*_xlfn.NORM.INV(RAND(),0,1)) -> 9.9859113 | H18: =$B5*EXP(($I5-$J6-($H5^2)/2)*(1/52)+$H5*SQRT(1/52)*_xlfn.NORM.INV(RAND(),0,1)) -> 9.9918032 | I18: =$B5*EXP(($I5-$J6-($H5^2)/2)*(1/52)+$H5*SQRT(1/52)*_xlfn.NORM.INV(RAND(),0,1)) -> 9.9875844 | ... SG18: =$B5*EXP(($I5-$J6-($H5^2)/2)*(1/52)+$H5*SQRT(1/52)*_xlfn.NORM.INV(RAND(),0,1)) -> 9.9868679
A19: 46001 | B19: =$B6*EXP(($I6-$J7-($H6^2)/2)*(1/52)+$H6*SQRT(1/52)*_xlfn.NORM.INV(RAND(),0,1)) -> 9.9363301 | C19: =$B6*EXP(($I6-$J7-($H6^2)/2)*(1/52)+$H6*SQRT(1/52)*_xlfn.NORM.INV(RAND(),0,1)) -> 9.9409645 | D19: =$B6*EXP(($I6-$J7-($H6^2)/2)*(1/52)+$H6*SQRT(1/52)*_xlfn.NORM.INV(RAND(),0,1)) -> 9.9392526 | E19: =$B6*EXP(($I6-$J7-($H6^2)/2)*(1/52)+$H6*SQRT(1/52)*_xlfn.NORM.INV(RAND(),0,1)) -> 9.9393572 | F19: =$B6*EXP(($I6-$J7-($H6^2)/2)*(1/52)+$H6*SQRT(1/52)*_xlfn.NORM.INV(RAND(),0,1)) -> 9.9348277 | G19: =$B6*EXP(($I6-$J7-($H6^2)/2)*(1/52)+$H6*SQRT(1/52)*_xlfn.NORM.INV(RAND(),0,1)) -> 9.9326899 | H19: =$B6*EXP(($I6-$J7-($H6^2)/2)*(1/52)+$H6*SQRT(1/52)*_xlfn.NORM.INV(RAND(),0,1)) -> 9.9413564 | I19: =$B6*EXP(($I6-$J7-($H6^2)/2)*(1/52)+$H6*SQRT(1/52)*_xlfn.NORM.INV(RAND(),0,1)) -> 9.9365979 | ... SG19: =$B6*EXP(($I6-$J7-($H6^2)/2)*(1/52)+$H6*SQRT(1/52)*_xlfn.NORM.INV(RAND(),0,1)) -> 9.9398397
A20: 10/19/2025 | B20: =$B7*EXP(($I7-$J8-($H7^2)/2)*(1/52)+$H7*SQRT(1/52)*_xlfn.NORM.INV(RAND(),0,1)) -> 9.8730704 | C20: =$B7*EXP(($I7-$J8-($H7^2)/2)*(1/52)+$H7*SQRT(1/52)*_xlfn.NORM.INV(RAND(),0,1)) -> 9.879225 | D20: =$B7*EXP(($I7-$J8-($H7^2)/2)*(1/52)+$H7*SQRT(1/52)*_xlfn.NORM.INV(RAND(),0,1)) -> 9.8713202 | E20: =$B7*EXP(($I7-$J8-($H7^2)/2)*(1/52)+$H7*SQRT(1/52)*_xlfn.NORM.INV(RAND(),0,1)) -> 9.8813129 | F20: =$B7*EXP(($I7-$J8-($H7^2)/2)*(1/52)+$H7*SQRT(1/52)*_xlfn.NORM.INV(RAND(),0,1)) -> 9.8832768 | G20: =$B7*EXP(($I7-$J8-($H7^2)/2)*(1/52)+$H7*SQRT(1/52)*_xlfn.NORM.INV(RAND(),0,1)) -> 9.8803874 | H20: =$B7*EXP(($I7-$J8-($H7^2)/2)*(1/52)+$H7*SQRT(1/52)*_xlfn.NORM.INV(RAND(),0,1)) -> 9.8802738 | I20: =$B7*EXP(($I7-$J8-($H7^2)/2)*(1/52)+$H7*SQRT(1/52)*_xlfn.NORM.INV(RAND(),0,1)) -> 9.8802846 | ... SG20: =$B7*EXP(($I7-$J8-($H7^2)/2)*(1/52)+$H7*SQRT(1/52)*_xlfn.NORM.INV(RAND(),0,1)) -> 9.8783502
A21: 10/26/2025 | B21: =$B8*EXP(($I8-$J9-($H8^2)/2)*(1/52)+$H8*SQRT(1/52)*_xlfn.NORM.INV(RAND(),0,1)) -> 9.8870326 | C21: =$B8*EXP(($I8-$J9-($H8^2)/2)*(1/52)+$H8*SQRT(1/52)*_xlfn.NORM.INV(RAND(),0,1)) -> 9.8901212 | D21: =$B8*EXP(($I8-$J9-($H8^2)/2)*(1/52)+$H8*SQRT(1/52)*_xlfn.NORM.INV(RAND(),0,1)) -> 9.8895564 | E21: =$B8*EXP(($I8-$J9-($H8^2)/2)*(1/52)+$H8*SQRT(1/52)*_xlfn.NORM.INV(RAND(),0,1)) -> 9.8860806 | F21: =$B8*EXP(($I8-$J9-($H8^2)/2)*(1/52)+$H8*SQRT(1/52)*_xlfn.NORM.INV(RAND(),0,1)) -> 9.8889252 | G21: =$B8*EXP(($I8-$J9-($H8^2)/2)*(1/52)+$H8*SQRT(1/52)*_xlfn.NORM.INV(RAND(),0,1)) -> 9.8907496 | H21: =$B8*EXP(($I8-$J9-($H8^2)/2)*(1/52)+$H8*SQRT(1/52)*_xlfn.NORM.INV(RAND(),0,1)) -> 9.8871449 | I21: =$B8*EXP(($I8-$J9-($H8^2)/2)*(1/52)+$H8*SQRT(1/52)*_xlfn.NORM.INV(RAND(),0,1)) -> 9.890097 | ... SG21: =$B8*EXP(($I8-$J9-($H8^2)/2)*(1/52)+$H8*SQRT(1/52)*_xlfn.NORM.INV(RAND(),0,1)) -> 9.8836333
A22: 45699 | B22: =$B9*EXP(($I9-$J10-($H9^2)/2)*(1/52)+$H9*SQRT(1/52)*_xlfn.NORM.INV(RAND(),0,1)) -> 9.8567735 | C22: =$B9*EXP(($I9-$J10-($H9^2)/2)*(1/52)+$H9*SQRT(1/52)*_xlfn.NORM.INV(RAND(),0,1)) -> 9.856065 | D22: =$B9*EXP(($I9-$J10-($H9^2)/2)*(1/52)+$H9*SQRT(1/52)*_xlfn.NORM.INV(RAND(),0,1)) -> 9.8603163 | E22: =$B9*EXP(($I9-$J10-($H9^2)/2)*(1/52)+$H9*SQRT(1/52)*_xlfn.NORM.INV(RAND(),0,1)) -> 9.851159 | F22: =$B9*EXP(($I9-$J10-($H9^2)/2)*(1/52)+$H9*SQRT(1/52)*_xlfn.NORM.INV(RAND(),0,1)) -> 9.8585213 | G22: =$B9*EXP(($I9-$J10-($H9^2)/2)*(1/52)+$H9*SQRT(1/52)*_xlfn.NORM.INV(RAND(),0,1)) -> 9.8545421 | H22: =$B9*EXP(($I9-$J10-($H9^2)/2)*(1/52)+$H9*SQRT(1/52)*_xlfn.NORM.INV(RAND(),0,1)) -> 9.8581803 | I22: =$B9*EXP(($I9-$J10-($H9^2)/2)*(1/52)+$H9*SQRT(1/52)*_xlfn.NORM.INV(RAND(),0,1)) -> 9.8559976 | ... SG22: =$B9*EXP(($I9-$J10-($H9^2)/2)*(1/52)+$H9*SQRT(1/52)*_xlfn.NORM.INV(RAND(),0,1)) -> 9.8566741
A23: 45911 | B23: =$B10*EXP(($I10-$J11-($H10^2)/2)*(1/52)+$H10*SQRT(1/52)*_xlfn.NORM.INV(RAND(),0,1)) -> 9.8949242 | C23: =$B10*EXP(($I10-$J11-($H10^2)/2)*(1/52)+$H10*SQRT(1/52)*_xlfn.NORM.INV(RAND(),0,1)) -> 9.8989199 | D23: =$B10*EXP(($I10-$J11-($H10^2)/2)*(1/52)+$H10*SQRT(1/52)*_xlfn.NORM.INV(RAND(),0,1)) -> 9.8961172 | E23: =$B10*EXP(($I10-$J11-($H10^2)/2)*(1/52)+$H10*SQRT(1/52)*_xlfn.NORM.INV(RAND(),0,1)) -> 9.898174 | F23: =$B10*EXP(($I10-$J11-($H10^2)/2)*(1/52)+$H10*SQRT(1/52)*_xlfn.NORM.INV(RAND(),0,1)) -> 9.8977354 | G23: =$B10*EXP(($I10-$J11-($H10^2)/2)*(1/52)+$H10*SQRT(1/52)*_xlfn.NORM.INV(RAND(),0,1)) -> 9.89682 | H23: =$B10*EXP(($I10-$J11-($H10^2)/2)*(1/52)+$H10*SQRT(1/52)*_xlfn.NORM.INV(RAND(),0,1)) -> 9.8958044 | I23: =$B10*EXP(($I10-$J11-($H10^2)/2)*(1/52)+$H10*SQRT(1/52)*_xlfn.NORM.INV(RAND(),0,1)) -> 9.9012185 | ... SG23: =$B10*EXP(($I10-$J11-($H10^2)/2)*(1/52)+$H10*SQRT(1/52)*_xlfn.NORM.INV(RAND(),0,1)) -> 9.8993928
